Workbook

Sheet موجودی
A1: ردیف | B1: دسته بندی | C1: محصول | D1: وزن | E1: عیار | F1: فی تهیه اجرت درصدی | G1: اجرت درصدی فروش | H1: فی تهیه اجرت مبلغی | I1: اجرت مبلغی فروش | J1: فی تهیه سنگ | K1: فی فروش سنگ | L1: رنگ | M1: نوع کالا | N1: سایز | O1: کد قدیمی | P1: وضعیت
A2: 1 | B2: وزنی | C2: GD02002967 - میرو | D2: 10.61 | E2: 750 | F2: 15 | G2: 21 | H2: 0 | I2: 0 | J2: 0 | K2: 0 | L2: زرد | M2: گردنبند | P2: =IF(OR(COUNTIF('ثبت لیبل'!$B$11:$B$1010,TRIM(LEFT(C2,FIND("-",C2&"-")-1)))>0,COUNTIF('ثبت لیبل'!$B$11:$B$1010,SUBSTITUTE(TRIM(LEFT(C2,FIND("-",C2&"-")-1)),"GD",""))>0),"موجود","") -> موجود
A3: 2 | B3: وزنی | C3: GD02002885 - ماهلین میوه | D3: 0.05 | E3: 750 | F3: 6 | G3: 6 | H3: 0 | I3: 0 | J3: 6160000 | K3: 6160000 | L3: دورنگ | M3: مدال | P3: =IF(OR(COUNTIF('ثبت لیبل'!$B$11:$B$1010,TRIM(LEFT(C3,FIND("-",C3&"-")-1)))>0,COUNTIF('ثبت لیبل'!$B$11:$B$1010,SUBSTITUTE(TRIM(LEFT(C3,FIND("-",C3&"-")-1)),"GD",""))>0),"موجود","")
A4: 3 | B4: وزنی | C4: GD02002886 - ماهلین میوه | D4: 0.05 | E4: 750 | F4: 6 | G4: 6 | H4: 0 | I4: 0 | J4: 6160000 | K4: 6160000 | L4: دورنگ | M4: مدال | P4: =IF(OR(COUNTIF('ثبت لیبل'!$B$11:$B$1010,TRIM(LEFT(C4,FIND("-",C4&"-")-1)))>0,COUNTIF('ثبت لیبل'!$B$11:$B$1010,SUBSTITUTE(TRIM(LEFT(C4,FIND("-",C4&"-")-1)),"GD",""))>0),"موجود","")
A5: 4 | B5: وزنی | C5: GD02002898 - ماهلین میوه | D5: 0.05 | E5: 750 | F5: 6 | G5: 6 | H5: 0 | I5: 0 | J5: 6160000 | K5: 6160000 | L5: دورنگ | M5: مدال | P5: =IF(OR(COUNTIF('ثبت لیبل'!$B$11:$B$1010,TRIM(LEFT(C5,FIND("-",C5&"-")-1)))>0,COUNTIF('ثبت لیبل'!$B$11:$B$1010,SUBSTITUTE(TRIM(LEFT(C5,FIND("-",C5&"-")-1)),"GD",""))>0),"موجود","")
A6: 5 | B6: وزنی | C6: GD02002899 - ماهلین میوه | D6: 0.05 | E6: 750 | F6: 6 | G6: 6 | H6: 0 | I6: 0 | J6: 6160000 | K6: 6160000 | L6: دورنگ | M6: مدال | P6: =IF(OR(COUNTIF('ثبت لیبل'!$B$11:$B$1010,TRIM(LEFT(C6,FIND("-",C6&"-")-1)))>0,COUNTIF('ثبت لیبل'!$B$11:$B$1010,SUBSTITUTE(TRIM(LEFT(C6,FIND("-",C6&"-")-1)),"GD",""))>0),"موجود","")
A7: 6 | B7: وزنی | C7: GD02002884 - ماهلین میوه | D7: 0.05 | E7: 750 | F7: 6 | G7: 6 | H7: 0 | I7: 0 | J7: 6160000 | K7: 6160000 | L7: دورنگ | M7: مدال | P7: =IF(OR(COUNTIF('ثبت لیبل'!$B$11:$B$1010,TRIM(LEFT(C7,FIND("-",C7&"-")-1)))>0,COUNTIF('ثبت لیبل'!$B$11:$B$1010,SUBSTITUTE(TRIM(LEFT(C7,FIND("-",C7&"-")-1)),"GD",""))>0),"موجود","")
A8: 7 | B8: وزنی | C8: GD02002891 - ماهلین میوه | D8: 0.05 | E8: 750 | F8: 6 | G8: 6 | H8: 0 | I8: 0 | J8: 6160000 | K8: 6160000 | L8: دورنگ | M8: مدال | P8: =IF(OR(COUNTIF('ثبت لیبل'!$B$11:$B$1010,TRIM(LEFT(C8,FIND("-",C8&"-")-1)))>0,COUNTIF('ثبت لیبل'!$B$11:$B$1010,SUBSTITUTE(TRIM(LEFT(C8,FIND("-",C8&"-")-1)),"GD",""))>0),"موجود","")
A9: 8 | B9: وزنی | C9: GD02002881 - ماهلین میوه | D9: 0.05 | E9: 750 | F9: 6 | G9: 6 | H9: 0 | I9: 0 | J9: 6160000 | K9: 6160000 | L9: دورنگ | M9: مدال | P9: =IF(OR(COUNTIF('ثبت لیبل'!$B$11:$B$1010,TRIM(LEFT(C9,FIND("-",C9&"-")-1)))>0,COUNTIF('ثبت لیبل'!$B$11:$B$1010,SUBSTITUTE(TRIM(LEFT(C9,FIND("-",C9&"-")-1)),"GD",""))>0),"موجود","")
A10: 9 | B10: وزنی | C10: GD02002888 - ماهلین میوه | D10: 0.05 | E10: 750 | F10: 6 | G10: 6 | H10: 0 | I10: 0 | J10: 6160000 | K10: 6160000 | L10: دورنگ | M10: مدال | P10: =IF(OR(COUNTIF('ثبت لیبل'!$B$11:$B$1010,TRIM(LEFT(C10,FIND("-",C10&"-")-1)))>0,COUNTIF('ثبت لیبل'!$B$11:$B$1010,SUBSTITUTE(TRIM(LEFT(C10,FIND("-",C10&"-")-1)),"GD",""))>0),"موجود","")
A11: 10 | B11: وزنی | C11: GD02002880 - دریایی | D11: 0.55 | E11: 750 | F11: 12 | G11: 12 | H11: 0 | I11: 0 | J11: 0 | K11: 0 | L11: زرد | M11: مدال | P11: =IF(OR(COUNTIF('ثبت لیبل'!$B$11:$B$1010,TRIM(LEFT(C11,FIND("-",C11&"-")-1)))>0,COUNTIF('ثبت لیبل'!$B$11:$B$1010,SUBSTITUTE(TRIM(LEFT(C11,FIND("-",C11&"-")-1)),"GD",""))>0),"موجود","")
A12: 11 | B12: وزنی | C12: GD02002878 - دریایی | D12: 0.95 | E12: 750 | F12: 12 | G12: 12 | H12: 0 | I12: 0 | J12: 0 | K12: 0 | L12: زرد | M12: مدال | P12: =IF(OR(COUNTIF('ثبت لیبل'!$B$11:$B$1010,TRIM(LEFT(C12,FIND("-",C12&"-")-1)))>0,COUNTIF('ثبت لیبل'!$B$11:$B$1010,SUBSTITUTE(TRIM(LEFT(C12,FIND("-",C12&"-")-1)),"GD",""))>0),"موجود","")
A13: 12 | B13: وزنی | C13: GD02002879 - دریایی | D13: 0.7 | E13: 750 | F13: 12 | G13: 12 | H13: 0 | I13: 0 | J13: 0 | K13: 0 | L13: زرد | M13: مدال | P13: =IF(OR(COUNTIF('ثبت لیبل'!$B$11:$B$1010,TRIM(LEFT(C13,FIND("-",C13&"-")-1)))>0,COUNTIF('ثبت لیبل'!$B$11:$B$1010,SUBSTITUTE(TRIM(LEFT(C13,FIND("-",C13&"-")-1)),"GD",""))>0),"موجود","")
... A191: 190 | B191: وزنی | C191: GD02001562 - تک نگین | D191: 1.86 | E191: 750 | F191: 11 | G191: 11 | H191: 0 | I191: 0 | J191: 0 | K191: 0 | L191: زرد | M191: بنگل | P191: =IF(OR(COUNTIF('ثبت لیبل'!$B$11:$B$1010,TRIM(LEFT(C191,FIND("-",C191&"-")-1)))>0,COUNTIF('ثبت لیبل'!$B$11:$B$1010,SUBSTITUTE(TRIM(LEFT(C191,FIND("-",C191&"-")-1)),"GD",""))>0),"موجود","")
A192: 191 | B192: وزنی | C192: GD02001734 - ماهلین | D192: 2.68 | E192: 750 | F192: 13 | H192: 0 | J192: 0 | L192: زرد | M192: سرویس | P192: =IF(OR(COUNTIF('ثبت لیبل'!$B$11:$B$1010,TRIM(LEFT(C192,FIND("-",C192&"-")-1)))>0,COUNTIF('ثبت لیبل'!$B$11:$B$1010,SUBSTITUTE(TRIM(LEFT(C192,FIND("-",C192&"-")-1)),"GD",""))>0),"موجود","")
A193: 192 | B193: وزنی | C193: GD02001553 - موجی | D193: 0.8 | E193: 750 | F193: 12 | G193: 12 | H193: 0 | I193: 0 | J193: 0 | K193: 0 | L193: زرد | M193: گوشواره | P193: =IF(OR(COUNTIF('ثبت لیبل'!$B$11:$B$1010,TRIM(LEFT(C193,FIND("-",C193&"-")-1)))>0,COUNTIF('ثبت لیبل'!$B$11:$B$1010,SUBSTITUTE(TRIM(LEFT(C193,FIND("-",C193&"-")-1)),"GD",""))>0),"موجود","")
A194: 193 | B194: وزنی | C194: GD02001557 - موجی | D194: 0.75 | E194: 750 | F194: 12 | G194: 12 | H194: 0 | I194: 0 | J194: 0 | K194: 0 | L194: زرد | M194: گوشواره | P194: =IF(OR(COUNTIF('ثبت لیبل'!$B$11:$B$1010,TRIM(LEFT(C194,FIND("-",C194&"-")-1)))>0,COUNTIF('ثبت لیبل'!$B$11:$B$1010,SUBSTITUTE(TRIM(LEFT(C194,FIND("-",C194&"-")-1)),"GD",""))>0),"موجود","")
A195: 194 | B195: وزنی | C195: GD02001558 - موجی | D195: 0.73 | E195: 750 | F195: 12 | G195: 12 | H195: 0 | I195: 0 | J195: 0 | K195: 0 | L195: زرد | M195: گوشواره | P195: =IF(OR(COUNTIF('ثبت لیبل'!$B$11:$B$1010,TRIM(LEFT(C195,FIND("-",C195&"-")-1)))>0,COUNTIF('ثبت لیبل'!$B$11:$B$1010,SUBSTITUTE(TRIM(LEFT(C195,FIND("-",C195&"-")-1)),"GD",""))>0),"موجود","")
A196: 195 | B196: وزنی | C196: GD02001556 - موجی | D196: 0.74 | E196: 750 | F196: 12 | G196: 12 | H196: 0 | I196: 0 | J196: 0 | K196: 0 | L196: زرد | M196: گوشواره | P196: =IF(OR(COUNTIF('ثبت لیبل'!$B$11:$B$1010,TRIM(LEFT(C196,FIND("-",C196&"-")-1)))>0,COUNTIF('ثبت لیبل'!$B$11:$B$1010,SUBSTITUTE(TRIM(LEFT(C196,FIND("-",C196&"-")-1)),"GD",""))>0),"موجود","")
A197: 196 | B197: وزنی | C197: GD02001555 - موجی | D197: 0.86 | E197: 750 | F197: 12 | G197: 12 | H197: 0 | I197: 0 | J197: 0 | K197: 0 | L197: زرد | M197: گوشواره | P197: =IF(OR(COUNTIF('ثبت لیبل'!$B$11:$B$1010,TRIM(LEFT(C197,FIND("-",C197&"-")-1)))>0,COUNTIF('ثبت لیبل'!$B$11:$B$1010,SUBSTITUTE(TRIM(LEFT(C197,FIND("-",C197&"-")-1)),"GD",""))>0),"موجود","")
A198: 197 | B198: وزنی | C198: GD02001554 - موجی | D198: 0.84 | E198: 750 | F198: 12 | G198: 12 | H198: 0 | I198: 0 | J198: 0 | K198: 0 | L198: زرد | M198: گوشواره | P198: =IF(OR(COUNTIF('ثبت لیبل'!$B$11:$B$1010,TRIM(LEFT(C198,FIND("-",C198&"-")-1)))>0,COUNTIF('ثبت لیبل'!$B$11:$B$1010,SUBSTITUTE(TRIM(LEFT(C198,FIND("-",C198&"-")-1)),"GD",""))>0),"موجود","")
A199: 198 | B199: وزنی | C199: GD02001540 - هندسی | D199: 1.33 | E199: 750 | F199: 11 | H199: 0 | J199: 0 | L199: زرد | M199: گوشواره | P199: =IF(OR(COUNTIF('ثبت لیبل'!$B$11:$B$1010,TRIM(LEFT(C199,FIND("-",C199&"-")-1)))>0,COUNTIF('ثبت لیبل'!$B$11:$B$1010,SUBSTITUTE(TRIM(LEFT(C199,FIND("-",C199&"-")-1)),"GD",""))>0),"موجود","")
A200: 199 | B200: وزنی | C200: GD02001541 - هندسی | D200: 1.13 | E200: 750 | F200: 11 | G200: 11 | H200: 0 | I200: 0 | J200: 0 | K200: 0 | L200: زرد | M200: گوشواره | P200: =IF(OR(COUNTIF('ثبت لیبل'!$B$11:$B$1010,TRIM(LEFT(C200,FIND("-",C200&"-")-1)))>0,COUNTIF('ثبت لیبل'!$B$11:$B$1010,SUBSTITUTE(TRIM(LEFT(C200,FIND("-",C200&"-")-1)),"GD",""))>0),"موجود","")
A201: 200 | B201: وزنی | C201: GD02001542 - هندسی | D201: 1.09 | E201: 750 | F201: 11 | G201: 11 | H201: 0 | I201: 0 | J201: 0 | K201: 0 | L201: زرد | M201: گوشواره | P201: =IF(OR(COUNTIF('ثبت لیبل'!$B$11:$B$1010,TRIM(LEFT(C201,FIND("-",C201&"-")-1)))>0,COUNTIF('ثبت لیبل'!$B$11:$B$1010,SUBSTITUTE(TRIM(LEFT(C201,FIND("-",C201&"-")-1)),"GD",""))>0),"موجود","")
A202: 201 | B202: وزنی | C202: GD02001545 - حلقه ای لوکس | D202: 0.91 | E202: 750 | F202: 10 | G202: 10 | H202: 0 | I202: 0 | J202: 0 | K202: 0 | L202: زرد | M202: گوشواره | P202: =IF(OR(COUNTIF('ثبت لیبل'!$B$11:$B$1010,TRIM(LEFT(C202,FIND("-",C202&"-")-1)))>0,COUNTIF('ثبت لیبل'!$B$11:$B$1010,SUBSTITUTE(TRIM(LEFT(C202,FIND("-",C202&"-")-1)),"GD",""))>0),"موجود","")
A203: 202 | B203: وزنی | C203: GD02001543 - هندسی | D203: 1.09 | E203: 750 | F203: 11 | G203: 11 | H203: 0 | I203: 0 | J203: 0 | K203: 0 | L203: زرد | M203: گوشواره | P203: =IF(OR(COUNTIF('ثبت لیبل'!$B$11:$B$1010,TRIM(LEFT(C203,FIND("-",C203&"-")-1)))>0,COUNTIF('ثبت لیبل'!$B$11:$B$1010,SUBSTITUTE(TRIM(LEFT(C203,FIND("-",C203&"-")-1)),"GD",""))>0),"موجود","")
A204: 203 | B204: سکه پارسیان | C204: GD01001619 - پارسیان | D204: 0.04 | E204: 750 | F204: 0 | G204: 0 | H204: 0 | I204: 0 | J204: 550000 | K204: 550000 | L204: زرد | M204: سکه | P204: =IF(OR(COUNTIF('ثبت لیبل'!$B$11:$B$1010,TRIM(LEFT(C204,FIND("-",C204&"-")-1)))>0,COUNTIF('ثبت لیبل'!$B$11:$B$1010,SUBSTITUTE(TRIM(LEFT(C204,FIND("-",C204&"-")-1)),"GD",""))>0),"موجود","")
A205: 204 | B205: سکه پارسیان | C205: GD01001601 - پارسیان | D205: 0.03 | E205: 750 | F205: 0 | G205: 0 | H205: 0 | I205: 0 | J205: 550000 | K205: 550000 | L205: زرد | M205: سکه | P205: =IF(OR(COUNTIF('ثبت لیبل'!$B$11:$B$1010,TRIM(LEFT(C205,FIND("-",C205&"-")-1)))>0,COUNTIF('ثبت لیبل'!$B$11:$B$1010,SUBSTITUTE(TRIM(LEFT(C205,FIND("-",C205&"-")-1)),"GD",""))>0),"موجود","")
A206: 205 | B206: سکه پارسیان | C206: GD01001620 - پارسیان | D206: 0.04 | E206: 750 | F206: 0 | G206: 0 | H206: 0 | I206: 0 | J206: 550000 | K206: 550000 | L206: زرد | M206: سکه | P206: =IF(OR(COUNTIF('ثبت لیبل'!$B$11:$B$1010,TRIM(LEFT(C206,FIND("-",C206&"-")-1)))>0,COUNTIF('ثبت لیبل'!$B$11:$B$1010,SUBSTITUTE(TRIM(LEFT(C206,FIND("-",C206&"-")-1)),"GD",""))>0),"موجود","")
A207: 206 | B207: سکه پارسیان | C207: GD01001602 - پارسیان | D207: 0.03 | E207: 750 | F207: 0 | G207: 0 | H207: 0 | I207: 0 | J207: 550000 | K207: 550000 | L207: زرد | M207: سکه | P207: =IF(OR(COUNTIF('ثبت لیبل'!$B$11:$B$1010,TRIM(LEFT(C207,FIND("-",C207&"-")-1)))>0,COUNTIF('ثبت لیبل'!$B$11:$B$1010,SUBSTITUTE(TRIM(LEFT(C207,FIND("-",C207&"-")-1)),"GD",""))>0),"موجود","")
A208: 207 | B208: سکه پارسیان | C208: GD01001652 - پارسیان | D208: 0.07 | E208: 750 | F208: 0 | G208: 0 | H208: 0 | I208: 0 | J208: 550000 | K208: 550000 | L208: زرد | M208: سکه | P208: =IF(OR(COUNTIF('ثبت لیبل'!$B$11:$B$1010,TRIM(LEFT(C208,FIND("-",C208&"-")-1)))>0,COUNTIF('ثبت لیبل'!$B$11:$B$1010,SUBSTITUTE(TRIM(LEFT(C208,FIND("-",C208&"-")-1)),"GD",""))>0),"موجود","")
A209: 208 | B209: سکه پارسیان | C209: GD01001603 - پارسیان | D209: 0.03 | E209: 750 | F209: 0 | G209: 0 | H209: 0 | I209: 0 | J209: 550000 | K209: 550000 | L209: زرد | M209: سکه | P209: =IF(OR(COUNTIF('ثبت لیبل'!$B$11:$B$1010,TRIM(LEFT(C209,FIND("-",C209&"-")-1)))>0,COUNTIF('ثبت لیبل'!$B$11:$B$1010,SUBSTITUTE(TRIM(LEFT(C209,FIND("-",C209&"-")-1)),"GD",""))>0),"موجود","")
A210: 209 | B210: سکه پارسیان | C210: GD01001653 - پارسیان | D210: 0.07 | E210: 750 | F210: 0 | G210: 0 | H210: 0 | I210: 0 | J210: 550000 | K210: 550000 | L210: زرد | M210: سکه | P210: =IF(OR(COUNTIF('ثبت لیبل'!$B$11:$B$1010,TRIM(LEFT(C210,FIND("-",C210&"-")-1)))>0,COUNTIF('ثبت لیبل'!$B$11:$B$1010,SUBSTITUTE(TRIM(LEFT(C210,FIND("-",C210&"-")-1)),"GD",""))>0),"موجود","")
A211: 210 | B211: سکه پارسیان | C211: GD01001586 - پارسیان | D211: 0.03 | E211: 750 | F211: 0 | G211: 0 | H211: 0 | I211: 0 | J211: 550000 | K211: 550000 | L211: زرد | M211: سکه | P211: =IF(OR(COUNTIF('ثبت لیبل'!$B$11:$B$1010,TRIM(LEFT(C211,FIND("-",C211&"-")-1)))>0,COUNTIF('ثبت لیبل'!$B$11:$B$1010,SUBSTITUTE(TRIM(LEFT(C211,FIND("-",C211&"-")-1)),"GD",""))>0),"موجود","")
... A300: 299 | B300: سکه پارسیان | C300: GD01001651 - پارسیان | D300: 0.05 | E300: 750 | F300: 0 | G300: 0 | H300: 0 | I300: 0 | J300: 550000 | K300: 550000 | L300: زرد | M300: سکه | P300: =IF(OR(COUNTIF('ثبت لیبل'!$B$11:$B$1010,TRIM(LEFT(C300,FIND("-",C300&"-")-1)))>0,COUNTIF('ثبت لیبل'!$B$11:$B$1010,SUBSTITUTE(TRIM(LEFT(C300,FIND("-",C300&"-")-1)),"GD",""))>0),"موجود","")
A301: 300 | B301: سکه پارسیان | C301: GD01001725 - پارسیان | D301: 0.25 | E301: 750 | F301: 0 | G301: 0 | H301: 0 | I301: 0 | J301: 550000 | K301: 550000 | P301: =IF(OR(COUNTIF('ثبت لیبل'!$B$11:$B$1010,TRIM(LEFT(C301,FIND("-",C301&"-")-1)))>0,COUNTIF('ثبت لیبل'!$B$11:$B$1010,SUBSTITUTE(TRIM(LEFT(C301,FIND("-",C301&"-")-1)),"GD",""))>0),"موجود","")
A302: 301 | B302: سکه پارسیان | C302: GD01001726 - پارسیان | D302: 0.25 | E302: 750 | F302: 0 | G302: 0 | H302: 0 | I302: 0 | J302: 550000 | K302: 550000 | L302: زرد | M302: سکه | P302: =IF(OR(COUNTIF('ثبت لیبل'!$B$11:$B$1010,TRIM(LEFT(C302,FIND("-",C302&"-")-1)))>0,COUNTIF('ثبت لیبل'!$B$11:$B$1010,SUBSTITUTE(TRIM(LEFT(C302,FIND("-",C302&"-")-1)),"GD",""))>0),"موجود","")
A303: 302 | B303: سکه پارسیان | C303: GD01001727 - پارسیان | D303: 0.25 | E303: 750 | F303: 0 | G303: 0 | H303: 0 | I303: 0 | J303: 550000 | K303: 550000 | L303: زرد | M303: سکه | P303: =IF(OR(COUNTIF('ثبت لیبل'!$B$11:$B$1010,TRIM(LEFT(C303,FIND("-",C303&"-")-1)))>0,COUNTIF('ثبت لیبل'!$B$11:$B$1010,SUBSTITUTE(TRIM(LEFT(C303,FIND("-",C303&"-")-1)),"GD",""))>0),"موجود","")
A304: 303 | B304: سکه پارسیان | C304: GD01001708 - پارسیان | D304: 0.5 | E304: 750 | F304: 0 | G304: 0 | H304: 0 | I304: 0 | J304: 550000 | K304: 550000 | L304: زرد | M304: سکه | P304: =IF(OR(COUNTIF('ثبت لیبل'!$B$11:$B$1010,TRIM(LEFT(C304,FIND("-",C304&"-")-1)))>0,COUNTIF('ثبت لیبل'!$B$11:$B$1010,SUBSTITUTE(TRIM(LEFT(C304,FIND("-",C304&"-")-1)),"GD",""))>0),"موجود","")
A305: 304 | B305: سکه پارسیان | C305: GD01001709 - پارسیان | D305: 0.5 | E305: 750 | F305: 0 | G305: 0 | H305: 0 | I305: 0 | J305: 550000 | K305: 550000 | L305: زرد | M305: سکه | P305: =IF(OR(COUNTIF('ثبت لیبل'!$B$11:$B$1010,TRIM(LEFT(C305,FIND("-",C305&"-")-1)))>0,COUNTIF('ثبت لیبل'!$B$11:$B$1010,SUBSTITUTE(TRIM(LEFT(C305,FIND("-",C305&"-")-1)),"GD",""))>0),"موجود","")
...

Sheet ثبت لیبل
A1: ثبت و کنترل شماره لیبل
A2: شماره لیبل را در ستون آبی وارد یا اسکن کنید؛ وضعیت به‌صورت خودکار نمایش داده می‌شود.
B4: خلاصه | C4: تعداد | E4: پنجره جستجو و ثبت لیبل
B5: کل لیبل‌های ثبت‌شده | C5: =COUNTA(B11:B1010) -> 4 | E5: روی دکمه زیر کلیک کرده و شماره لیبل را وارد کنید
B6: موجود | C6: =COUNTIF(C11:C1010,"موجود") -> 2 | E6: ردیف آماده ثبت | F6: {=IFERROR(_xlfn.AGGREGATE(15,6,ROW(B11:B1010)/(B11:B1010=""),1),"ظرفیت تکمیل")} -> 15
B7: مغایرت | C7: =COUNTIF(C11:C1010,"مغایرت") -> 2 | E7: {=IFERROR(HYPERLINK("#'ثبت لیبل'!B"&_xlfn.AGGREGATE(15,6,ROW(B11:B1010)/(B11:B1010=""),1),"ورود / جستجوی شماره لیبل"),"ظرفیت جدول تکمیل است")} -> ورود / جستجوی شماره لیبل
E8: پس از ورود، نتیجه جستجو در همان ردیف ثبت می‌شود
B9: شماره لیبل | C9: نتیجه جستجو
B11: 02002967 | C11: =IF(B11="","",IF(COUNTIF(موجودی!$C$2:$C$839,"*"&B11&"*")>0,"موجود","مغایرت")) -> موجود
B12: GD02002967 | C12: =IF(B12="","",IF(COUNTIF(موجودی!$C$2:$C$839,"*"&B12&"*")>0,"موجود","مغایرت")) -> موجود
B13: 00200 | C13: =IF(B13="","",IF(COUNTIF(موجودی!$C$2:$C$839,"*"&B13&"*")>0,"موجود","مغایرت")) -> مغایرت
B14: 003000 | C14: =IF(B14="","",IF(COUNTIF(موجودی!$C$2:$C$839,"*"&B14&"*")>0,"موجود","مغایرت")) -> مغایرت
C15: =IF(B15="","",IF(COUNTIF(موجودی!$C$2:$C$839,"*"&B15&"*")>0,"موجود","مغایرت"))
C16: =IF(B16="","",IF(COUNTIF(موجودی!$C$2:$C$839,"*"&B16&"*")>0,"موجود","مغایرت"))
C17: =IF(B17="","",IF(COUNTIF(موجودی!$C$2:$C$839,"*"&B17&"*")>0,"موجود","مغایرت"))
C18: =IF(B18="","",IF(COUNTIF(موجودی!$C$2:$C$839,"*"&B18&"*")>0,"موجود","مغایرت"))
C19: =IF(B19="","",IF(COUNTIF(موجودی!$C$2:$C$839,"*"&B19&"*")>0,"موجود","مغایرت"))
C20: =IF(B20="","",IF(COUNTIF(موجودی!$C$2:$C$839,"*"&B20&"*")>0,"موجود","مغایرت"))
C21: =IF(B21="","",IF(COUNTIF(موجودی!$C$2:$C$839,"*"&B21&"*")>0,"موجود","مغایرت"))
C22: =IF(B22="","",IF(COUNTIF(موجودی!$C$2:$C$839,"*"&B22&"*")>0,"موجود","مغایرت"))
C23: =IF(B23="","",IF(COUNTIF(موجودی!$C$2:$C$839,"*"&B23&"*")>0,"موجود","مغایرت"))
C24: =IF(B24="","",IF(COUNTIF(موجودی!$C$2:$C$839,"*"&B24&"*")>0,"موجود","مغایرت"))
C25: =IF(B25="","",IF(COUNTIF(موجودی!$C$2:$C$839,"*"&B25&"*")>0,"موجود","مغایرت"))
C26: =IF(B26="","",IF(COUNTIF(موجودی!$C$2:$C$839,"*"&B26&"*")>0,"موجود","مغایرت"))
... C1010: =IF(B1010="","",IF(COUNTIF(موجودی!$C$2:$C$839,"*"&B1010&"*")>0,"موجود","مغایرت"))

Sheet مغایرت
A1: گزارش مغایرت شماره لیبل
A2: این فهرست به‌صورت خودکار از شماره‌هایی که در موجودی یافت نمی‌شوند، تشکیل می‌شود.
A4: شماره لیبل مغایرت | B4: وضعیت
A5: {=_xlfn._xlws.FILTER('ثبت لیبل'!B11:C1010,'ثبت لیبل'!C11:C1010="مغایرت","مغایرتی ثبت نشده")} -> 00200 | B5: مغایرت
A6: 003000 | B6: مغایرت

Sheet طرح نرم افزار
A1: طرح نرم‌افزار ویندوز مغایرت‌گیری موجودی و لیبل
A2: نسخه پیشنهادی 1.0 | طراحی بر اساس فایل اکسل فعلی | تاریخ طراحی: 1405/07/15
A4: هدف: بارگذاری فایل Excel موجودی، تشخیص خودکار ستون لیبل، ثبت لیبل با بارکدخوان یا فایل، مغایرت‌گیری و خروجی Excel
A6: نوع برنامه | B6: Windows Desktop | D6: روش ورود | E6: اسکن تکی + Excel | G6: تشخیص ستون | H6: خودکار + تأیید کاربر | I6: ذخیره‌سازی | J6: SQLite محلی
A9: گردش کار اصلی نرم‌افزار
A10: مرحله | B10: عملکرد | D10: صفحه | E10: اجزای اصلی | F10: عملیات
A11: 1 | B11: ایجاد پروژه شمارش جدید و انتخاب نام/تاریخ پروژه | D11: خانه | E11: پروژه جدید، پروژه‌های قبلی | F11: ایجاد، بازکردن، حذف نسخه پشتیبان
A12: 2 | B12: بارگذاری فایل Excel موجودی (.xlsx یا .xls) | D12: بارگذاری موجودی | E12: انتخاب فایل، نام شیت، تشخیص ستون | F12: پیش‌نمایش و تأیید
A13: 3 | B13: خواندن سرستون‌ها و تشخیص خودکار ستون دارای کد/محصول/لیبل | D13: شمارش تکی | E13: کادر بزرگ اسکن، آخرین نتیجه، آمار | F13: ثبت با Enter و پخش هشدار
A14: 4 | B14: نمایش نمونه 10 ردیف و دریافت تأیید ستون تشخیص‌داده‌شده | D14: ورود گروهی | E14: انتخاب Excel لیبل‌ها و ستون کد | F14: پاک‌سازی و ورود دسته‌ای
A15: 5 | B15: ثبت لیبل با بارکدخوان/کیبورد یا بارگذاری فایل لیبل‌ها | D15: نتایج | E15: تب موجود، مغایرت، تکراری، شمارش‌نشده | F15: جستجو، فیلتر و مرتب‌سازی
A16: 6 | B16: مقایسه لحظه‌ای و نمایش موجود، مغایرت، تکراری و شمارش‌نشده | D16: گزارش | E16: خلاصه آماری و جزئیات | F16: خروجی Excel و چاپ
A17: 7 | B17: ذخیره پروژه و خروجی گرفتن به Excel | D17: تنظیمات | E17: الگوی کد، حذف پیشوند، صدا، رنگ | F17: ذخیره تنظیمات پیش‌فرض
A20: منطق تشخیص خودکار ستون لیبل
A21: اولویت | B21: روش تشخیص | C21: امتیاز پیشنهادی | E21: قاعده نرمال‌سازی | F21: نمونه ورودی | G21: مقدار مقایسه | H21: رفتار | I21: تنظیم‌پذیر | J21: وضعیت
A22: 1 | B22: نام ستون شامل لیبل، کد، محصول، barcode یا item code | C22: 50 | E22: حذف فاصله ابتدا/انتها | F22: GD02002967 | G22: GD02002967 | H22: خودکار | I22: خیر | J22: فعال
A23: 2 | B23: درصد بالای مقادیر یکتا در ستون | C23: 20 | E23: حذف متن بعد از خط تیره | F23: GD02002967 - میرو | G23: GD02002967 | H23: خودکار | I23: بله | J23: فعال
A24: 3 | B24: وجود الگوی حروف و عدد مانند GD02002967 | C24: 20 | E24: یکسان‌سازی حروف | F24: gd02002967 | G24: GD02002967 | H24: خودکار | I24: خیر | J24: فعال
A25: 4 | B25: وجود جداکننده و کد در ابتدای متن مانند کد - نام محصول | C25: 10 | E25: پشتیبانی بدون پیشوند | F25: 2002967 | G25: GD02002967 | H25: با تنظیم GD | I25: بله | J25: فعال
A26: کنترل | B26: نمایش نمونه و تأیید دستی کاربر قبل از شروع | C26: اجباری | E26: حفظ صفر ابتدایی | F26: 2002967 | G26: 2002967 | H26: متن | I26: خیر | J26: فعال
E27: رد مقدار خالی | G27: ثبت نمی‌شود | H27: هشدار | I27: خیر | J27: فعال
A30: وضعیت‌های مغایرت‌گیری
A31: وضعیت | B31: تعریف | D31: رنگ | E31: رفتار رابط | F31: صدای پیشنهادی
A32: موجود | B32: لیبل ثبت‌شده در فایل موجودی وجود دارد | D32: سبز | E32: نمایش مشخصات کالا و افزایش شمارنده موجود | F32: تأیید کوتاه
A33: مغایرت | B33: لیبل ثبت‌شده در فایل موجودی پیدا نشد | D33: قرمز | E33: ثبت در لیست مغایرت و نمایش هشدار | F33: هشدار
A34: تکراری | B34: یک لیبل بیش از یک بار اسکن یا وارد شده است | D34: نارنجی | E34: عدم افزایش موجود و ثبت دفعات | F34: هشدار دوبل
A35: شمارش‌نشده | B35: کالای موجود در فایل موجودی هنوز اسکن نشده است | D35: خاکستری | E35: فقط در گزارش نهایی | F35: بدون صدا
A36: کد نامعتبر | B36: مقدار با قواعد حداقل طول یا الگوی تعیین‌شده سازگار نیست | D36: قرمز تیره | E36: عدم ثبت تا تأیید یا اصلاح | F36: هشدار
A39: ساختار داده و فناوری پیشنهادی
A40: بخش | B40: پیشنهاد | D40: جدول داده | E40: فیلدهای کلیدی | F40: کلید | G40: منبع | H40: قابل ویرایش | I40: حذف | J40: یادداشت
A41: زبان | B41: Python 3.12 | D41: projects | E41: id, name, created_at, inventory_file | F41: id | G41: برنامه | H41: بله | I41: بله | J41: اطلاعات پروژه
A42: رابط کاربری | B42: PySide6 (Qt) با پشتیبانی کامل فارسی و RTL | D42: inventory | E42: project_id, label, raw_value, row_data | F42: project_id+label | G42: Excel موجودی | H42: خیر | I42: با پروژه | J42: کلیه ستون‌ها در JSON
A43: خواندن Excel | B43: pandas + openpyxl | D43: scans | E43: project_id, label, scanned_at, source, status | F43: id | G43: اسکن/Excel | H43: بله | I43: بله | J43: ثبت تاریخ و منبع
A44: پایگاه داده | B44: SQLite برای ذخیره پروژه‌ها و اسکن‌ها | D44: settings | E44: prefix, delimiter, min_length, sound | F44: key | G44: کاربر | H44: بله | I44: بازنشانی | J44: تنظیمات عمومی
A45: خروجی | B45: openpyxl برای Excel قالب‌بندی‌شده | D45: imports | E45: file_name, sheet_name, column_name, row_count | F45: id | G45: فایل | H45: خیر | I45: خیر | J45: سوابق بارگذاری
A46: بسته نصب | B46: PyInstaller برای تولید فایل Setup/EXE
A47: سیستم عامل | B47: Windows 10 و Windows 11 - نسخه 64 بیت
A50: خروجی Excel نرم‌افزار
A51: شیت خروجی | B51: محتوا | C51: قالب | E51: ستون خروجی مغایرت | F51: نوع | G51: اجباری | H51: نمونه | I51: منبع | J51: توضیح
A52: خلاصه | B52: تعداد موجودی، اسکن‌شده، موجود، مغایرت، تکراری و شمارش‌نشده | C52: کارت آماری و نمودار ساده | E52: شماره لیبل | F52: متن | G52: بله | H52: 2002967 | I52: اسکن | J52: صفر ابتدایی حفظ شود
...
